<?xml version = "1.0" ?>
<robot name = "Self_Balancing_Robot" xmlns:xacro ="http://ros.org/wiki/xacro" >
	
	<link name = "Chassis">
		<inertial>
			<origin xyz = "0.0375 0 0" rpy = "0 0 0" />
			<mass value = "0.388"/>
			<inertia ixx ="0.0113" iyy=".01094" izz=".00971" ixy="0" ixz ="0" iyz = "0"/>
		</inertial>
		<collision>
			<geometry>
				<box size = "0.075 0.175 0.157" /> <!-- 0.075 0.175 0.157 -->			 
			</geometry>
			<origin xyz = "0 0 0" rpy = "0 0 0"/>
		</collision>
		<visual>
			<geometry>
				<!--<box size = "0.075 0.175 0.157"/> -->
				<mesh filename = "/home/rafael/Documents/tcc/self_balancing_robot/urdf/meshes/Assem_No_wheel.dae" scale = "0.001 0.001 0.001" />
			</geometry>
			<origin xyz ="0.0 0.0 0.0055" rpy = "0 0 0" />
		</visual>
	</link>

	<link name = "Right_Wheel">
		<inertial>
			<origin xyz = "0.0 0.0185 0" rpy = "0 0 0" />
			<mass value ="0.03770"/>
			<inertia ixx ="0.000096758" ixz = "0.0" iyy = "0.000068429" iyz = "0.0000" ixy = "0.0" izz = "0.000096758"/>
		</inertial>
		<collision>
			<geometry>
				<cylinder radius="0.0316" length ="0.037"/>		
			</geometry>
			<origin rpy = "1.5708 0 0" xyz = "0 0.0150 0"/>
		</collision>
		<visual>
			<geometry>
				<mesh filename="/home/rafael/Documents/tcc/self_balancing_robot/urdf/meshes/WheelZTiny.dae"/>
			</geometry>
			<origin rpy = "0 0 0" xyz = "0 0.0 0"/>
		</visual>
	</link>

	<joint name ="Right_wheel_Joint" type = "continuous">
		<parent link = "Chassis"/>
		<child link = "Right_Wheel"/>
		<origin xyz = "0 0.0875 -0.0785" rpy ="0 0 0.0"/>
		<limit effort="100000" velocity="100000"/>
        <axis xyz="0 1 0"/>
	</joint>

	<link name = "Left_Wheel">
		<inertial>
			<origin xyz = "0.0 0.0185 0" rpy = "0 0 0" />
			<mass value ="0.03770"/>
			<inertia ixx ="0.000096758" ixz = "0.0" iyy = "0.000068429" iyz = "0.0000" ixy = "0.0" izz = "0.000096758"/>
		</inertial>
		<collision>
			<geometry>
				<cylinder radius="0.0316" length ="0.037"/>		
			</geometry>
			<origin rpy = "1.5708 0 0" xyz = "0 -0.015 0"/>
		</collision>
		<visual>
			<geometry>
				<mesh filename="/home/rafael/Documents/tcc/self_balancing_robot/urdf/meshes/WheelZTiny.dae"/>
			</geometry>
			<origin rpy = "0 0 0" xyz = "0 0.0 0"/>
		</visual>
	</link>
	
	<joint name ="Left_wheel_Joint" type = "continuous">
		<parent link = "Chassis"/>
		<child link = "Left_Wheel"/>
		<origin xyz = "0 -0.0875 -0.0785" rpy ="0 0 0.0"/>
		<limit effort="100000" velocity="100000"/>
        <axis xyz="0 1 0"/>
	</joint>
</robot>
